<?xml version="1.0" encoding="utf-8"?>
<!-- Ichika VRM Character URDF for Locomotion -->
<robot name="ichika">
    
    <!-- Base/Torso Link -->
    <link name="base">
        <visual>
            <origin rpy="0 0 0" xyz="0 0 0"/>
            <geometry>
                <box size="0.4 0.24 0.8"/>
            </geometry>
        </visual>
        <collision>
            <origin rpy="0 0 0" xyz="0 0 0"/>
            <geometry>
                <box size="0.4 0.24 0.8"/>
            </geometry>
        </collision>
        <inertial>
            <origin rpy="0 0 0" xyz="0 0 0"/>
            <mass value="10.0"/>
            <inertia ixx="0.5" ixy="0" ixz="0" iyy="0.5" iyz="0" izz="0.3"/>
        </inertial>
    </link>

    <!-- Head Link -->
    <link name="head">
        <visual>
            <origin rpy="0 0 0" xyz="0 0 0"/>
            <geometry>
                <sphere radius="0.3"/>
            </geometry>
        </visual>
        <collision>
            <origin rpy="0 0 0" xyz="0 0 0"/>
            <geometry>
                <sphere radius="0.3"/>
            </geometry>
        </collision>
        <inertial>
            <origin rpy="0 0 0" xyz="0 0 0"/>
            <mass value="2.0"/>
            <inertia ixx="0.05" ixy="0" ixz="0" iyy="0.05" iyz="0" izz="0.05"/>
        </inertial>
    </link>

    <!-- Neck Joint -->
    <joint name="neck_joint" type="revolute">
        <parent link="base"/>
        <child link="head"/>
        <origin rpy="0 0 0" xyz="0 0 0.7"/>
        <axis xyz="0 0 1"/>
        <limit effort="50" lower="-0.5" upper="0.5" velocity="2.0"/>
        <dynamics damping="1.0" friction="0.1"/>
    </joint>

    <!-- Left Upper Arm -->
    <link name="left_upper_arm">
        <visual>
            <origin rpy="0 1.57 0" xyz="0 0 0"/>
            <geometry>
                <cylinder radius="0.08" length="0.4"/>
            </geometry>
        </visual>
        <collision>
            <origin rpy="0 1.57 0" xyz="0 0 0"/>
            <geometry>
                <cylinder radius="0.08" length="0.4"/>
            </geometry>
        </collision>
        <inertial>
            <origin rpy="0 0 0" xyz="0 0 0"/>
            <mass value="1.5"/>
            <inertia ixx="0.02" ixy="0" ixz="0" iyy="0.02" iyz="0" izz="0.005"/>
        </inertial>
    </link>

    <!-- Left Shoulder Joint -->
    <joint name="left_shoulder_joint" type="revolute">
        <parent link="base"/>
        <child link="left_upper_arm"/>
        <origin rpy="0 0 0" xyz="-0.3 0 0.3"/>
        <axis xyz="0 1 0"/>
        <limit effort="80" lower="-1.5" upper="1.5" velocity="3.0"/>
        <dynamics damping="2.0" friction="0.2"/>
    </joint>

    <!-- Left Forearm -->
    <link name="left_forearm">
        <visual>
            <origin rpy="0 1.57 0" xyz="0 0 0"/>
            <geometry>
                <cylinder radius="0.06" length="0.3"/>
            </geometry>
        </visual>
        <collision>
            <origin rpy="0 1.57 0" xyz="0 0 0"/>
            <geometry>
                <cylinder radius="0.06" length="0.3"/>
            </geometry>
        </collision>
        <inertial>
            <origin rpy="0 0 0" xyz="0 0 0"/>
            <mass value="1.0"/>
            <inertia ixx="0.01" ixy="0" ixz="0" iyy="0.01" iyz="0" izz="0.003"/>
        </inertial>
    </link>

    <!-- Left Elbow Joint -->
    <joint name="left_elbow_joint" type="revolute">
        <parent link="left_upper_arm"/>
        <child link="left_forearm"/>
        <origin rpy="0 0 0" xyz="-0.4 0 0"/>
        <axis xyz="0 1 0"/>
        <limit effort="60" lower="-2.5" upper="0.1" velocity="3.0"/>
        <dynamics damping="1.5" friction="0.15"/>
    </joint>

    <!-- Right Upper Arm -->
    <link name="right_upper_arm">
        <visual>
            <origin rpy="0 1.57 0" xyz="0 0 0"/>
            <geometry>
                <cylinder radius="0.08" length="0.4"/>
            </geometry>
        </visual>
        <collision>
            <origin rpy="0 1.57 0" xyz="0 0 0"/>
            <geometry>
                <cylinder radius="0.08" length="0.4"/>
            </geometry>
        </collision>
        <inertial>
            <origin rpy="0 0 0" xyz="0 0 0"/>
            <mass value="1.5"/>
            <inertia ixx="0.02" ixy="0" ixz="0" iyy="0.02" iyz="0" izz="0.005"/>
        </inertial>
    </link>

    <!-- Right Shoulder Joint -->
    <joint name="right_shoulder_joint" type="revolute">
        <parent link="base"/>
        <child link="right_upper_arm"/>
        <origin rpy="0 0 0" xyz="0.3 0 0.3"/>
        <axis xyz="0 1 0"/>
        <limit effort="80" lower="-1.5" upper="1.5" velocity="3.0"/>
        <dynamics damping="2.0" friction="0.2"/>
    </joint>

    <!-- Right Forearm -->
    <link name="right_forearm">
        <visual>
            <origin rpy="0 1.57 0" xyz="0 0 0"/>
            <geometry>
                <cylinder radius="0.06" length="0.3"/>
            </geometry>
        </visual>
        <collision>
            <origin rpy="0 1.57 0" xyz="0 0 0"/>
            <geometry>
                <cylinder radius="0.06" length="0.3"/>
            </geometry>
        </collision>
        <inertial>
            <origin rpy="0 0 0" xyz="0 0 0"/>
            <mass value="1.0"/>
            <inertia ixx="0.01" ixy="0" ixz="0" iyy="0.01" iyz="0" izz="0.003"/>
        </inertial>
    </link>

    <!-- Right Elbow Joint -->
    <joint name="right_elbow_joint" type="revolute">
        <parent link="right_upper_arm"/>
        <child link="right_forearm"/>
        <origin rpy="0 0 0" xyz="0.4 0 0"/>
        <axis xyz="0 1 0"/>
        <limit effort="60" lower="-2.5" upper="0.1" velocity="3.0"/>
        <dynamics damping="1.5" friction="0.15"/>
    </joint>

    <!-- Left Thigh -->
    <link name="left_thigh">
        <visual>
            <origin rpy="0 0 0" xyz="0 0 0"/>
            <geometry>
                <cylinder radius="0.1" length="0.5"/>
            </geometry>
        </visual>
        <collision>
            <origin rpy="0 0 0" xyz="0 0 0"/>
            <geometry>
                <cylinder radius="0.1" length="0.5"/>
            </geometry>
        </collision>
        <inertial>
            <origin rpy="0 0 0" xyz="0 0 0"/>
            <mass value="3.0"/>
            <inertia ixx="0.05" ixy="0" ixz="0" iyy="0.05" iyz="0" izz="0.01"/>
        </inertial>
    </link>

    <!-- Left Hip Joint -->
    <joint name="left_hip_joint" type="revolute">
        <parent link="base"/>
        <child link="left_thigh"/>
        <origin rpy="0 0 0" xyz="-0.15 0 -0.6"/>
        <axis xyz="0 1 0"/>
        <limit effort="150" lower="-1.0" upper="1.0" velocity="4.0"/>
        <dynamics damping="3.0" friction="0.3"/>
    </joint>

    <!-- Left Shin -->
    <link name="left_shin">
        <visual>
            <origin rpy="0 0 0" xyz="0 0 0"/>
            <geometry>
                <cylinder radius="0.08" length="0.4"/>
            </geometry>
        </visual>
        <collision>
            <origin rpy="0 0 0" xyz="0 0 0"/>
            <geometry>
                <cylinder radius="0.08" length="0.4"/>
            </geometry>
        </collision>
        <inertial>
            <origin rpy="0 0 0" xyz="0 0 0"/>
            <mass value="2.0"/>
            <inertia ixx="0.03" ixy="0" ixz="0" iyy="0.03" iyz="0" izz="0.005"/>
        </inertial>
    </link>

    <!-- Left Knee Joint -->
    <joint name="left_knee_joint" type="revolute">
        <parent link="left_thigh"/>
        <child link="left_shin"/>
        <origin rpy="0 0 0" xyz="0 0 -0.5"/>
        <axis xyz="0 1 0"/>
        <limit effort="120" lower="-2.5" upper="0.1" velocity="4.0"/>
        <dynamics damping="2.5" friction="0.25"/>
    </joint>

    <!-- Left Foot -->
    <link name="left_foot">
        <visual>
            <origin rpy="0 0 0" xyz="0 0 0"/>
            <geometry>
                <box size="0.15 0.25 0.08"/>
            </geometry>
        </visual>
        <collision>
            <origin rpy="0 0 0" xyz="0 0 0"/>
            <geometry>
                <box size="0.15 0.25 0.08"/>
            </geometry>
        </collision>
        <inertial>
            <origin rpy="0 0 0" xyz="0 0 0"/>
            <mass value="1.0"/>
            <inertia ixx="0.01" ixy="0" ixz="0" iyy="0.01" iyz="0" izz="0.01"/>
        </inertial>
    </link>

    <!-- Left Ankle Joint -->
    <joint name="left_ankle_joint" type="revolute">
        <parent link="left_shin"/>
        <child link="left_foot"/>
        <origin rpy="0 0 0" xyz="0 0.05 -0.4"/>
        <axis xyz="0 1 0"/>
        <limit effort="80" lower="-0.5" upper="0.5" velocity="3.0"/>
        <dynamics damping="1.0" friction="0.2"/>
    </joint>

    <!-- Right Thigh -->
    <link name="right_thigh">
        <visual>
            <origin rpy="0 0 0" xyz="0 0 0"/>
            <geometry>
                <cylinder radius="0.1" length="0.5"/>
            </geometry>
        </visual>
        <collision>
            <origin rpy="0 0 0" xyz="0 0 0"/>
            <geometry>
                <cylinder radius="0.1" length="0.5"/>
            </geometry>
        </collision>
        <inertial>
            <origin rpy="0 0 0" xyz="0 0 0"/>
            <mass value="3.0"/>
            <inertia ixx="0.05" ixy="0" ixz="0" iyy="0.05" iyz="0" izz="0.01"/>
        </inertial>
    </link>

    <!-- Right Hip Joint -->
    <joint name="right_hip_joint" type="revolute">
        <parent link="base"/>
        <child link="right_thigh"/>
        <origin rpy="0 0 0" xyz="0.15 0 -0.6"/>
        <axis xyz="0 1 0"/>
        <limit effort="150" lower="-1.0" upper="1.0" velocity="4.0"/>
        <dynamics damping="3.0" friction="0.3"/>
    </joint>

    <!-- Right Shin -->
    <link name="right_shin">
        <visual>
            <origin rpy="0 0 0" xyz="0 0 0"/>
            <geometry>
                <cylinder radius="0.08" length="0.4"/>
            </geometry>
        </visual>
        <collision>
            <origin rpy="0 0 0" xyz="0 0 0"/>
            <geometry>
                <cylinder radius="0.08" length="0.4"/>
            </geometry>
        </collision>
        <inertial>
            <origin rpy="0 0 0" xyz="0 0 0"/>
            <mass value="2.0"/>
            <inertia ixx="0.03" ixy="0" ixz="0" iyy="0.03" iyz="0" izz="0.005"/>
        </inertial>
    </link>

    <!-- Right Knee Joint -->
    <joint name="right_knee_joint" type="revolute">
        <parent link="right_thigh"/>
        <child link="right_shin"/>
        <origin rpy="0 0 0" xyz="0 0 -0.5"/>
        <axis xyz="0 1 0"/>
        <limit effort="120" lower="-2.5" upper="0.1" velocity="4.0"/>
        <dynamics damping="2.5" friction="0.25"/>
    </joint>

    <!-- Right Foot -->
    <link name="right_foot">
        <visual>
            <origin rpy="0 0 0" xyz="0 0 0"/>
            <geometry>
                <box size="0.15 0.25 0.08"/>
            </geometry>
        </visual>
        <collision>
            <origin rpy="0 0 0" xyz="0 0 0"/>
            <geometry>
                <box size="0.15 0.25 0.08"/>
            </geometry>
        </collision>
        <inertial>
            <origin rpy="0 0 0" xyz="0 0 0"/>
            <mass value="1.0"/>
            <inertia ixx="0.01" ixy="0" ixz="0" iyy="0.01" iyz="0" izz="0.01"/>
        </inertial>
    </link>

    <!-- Right Ankle Joint -->
    <joint name="right_ankle_joint" type="revolute">
        <parent link="right_shin"/>
        <child link="right_foot"/>
        <origin rpy="0 0 0" xyz="0 0.05 -0.4"/>
        <axis xyz="0 1 0"/>
        <limit effort="80" lower="-0.5" upper="0.5" velocity="3.0"/>
        <dynamics damping="1.0" friction="0.2"/>
    </joint>

</robot>
